Workbook
Name UPDATE: '[1]Data Sheet'!$E$1
Name UPDATE: '[1]Data Sheet'!$E$1
Name UPDATE: '[1]Data Sheet'!$E$1
Name UPDATE: '[1]Data Sheet'!$E$1
Name UPDATE: 'Data Sheet'!$E$1

Sheet Financials>

Sheet Historical FS
B2: ="Historical Financial Statements - "& 'Data Sheet'!B1 -> Historical Financial Statements - HINDUSTAN UNILEVER LTD
B3: Years | C3: ='[1]Data Sheet'!B16 -> 42825 | D3: ='[1]Data Sheet'!C16 -> 43190 | E3: ='[1]Data Sheet'!D16 -> 43555 | F3: ='[1]Data Sheet'!E16 -> 43921 | G3: ='[1]Data Sheet'!F16 -> 44286 | H3: ='[1]Data Sheet'!G16 -> 44651 | I3: ='[1]Data Sheet'!H16 -> 45016 | J3: ='[1]Data Sheet'!I16 -> 45382 | ... L3: ='[1]Data Sheet'!K16 -> 46112
A4: # | B4: Income Statement
B5: Sales | C5: =IFERROR('Data Sheet'!B17,0) -> 33162 | D5: =IFERROR('Data Sheet'!C17,0) -> 35545 | E5: =IFERROR('Data Sheet'!D17,0) -> 39310 | F5: =IFERROR('Data Sheet'!E17,0) -> 39783 | G5: =IFERROR('Data Sheet'!F17,0) -> 47028 | H5: =IFERROR('Data Sheet'!G17,0) -> 52446 | I5: =IFERROR('Data Sheet'!H17,0) -> 60580 | J5: =IFERROR('Data Sheet'!I17,0) -> 61896 | ... L5: =IFERROR('Data Sheet'!K17,0) -> 64468
B6: Sales Growth | C6: - | D6: =D5/C5-1 -> 0.071859357 | E6: =E5/D5-1 -> 0.10592207 | F6: =F5/E5-1 -> 0.012032562 | G6: =G5/F5-1 -> 0.18211296 | H6: =H5/G5-1 -> 0.11520796 | I6: =I5/H5-1 -> 0.15509286 | J6: =J5/I5-1 -> 0.021723341 | K6: =K5/J5-1 -> -0.0091766835 | L6: =L5/K5-1 -> 0.051200104
B8: COGS | C8: =IFERROR(SUM('Data Sheet'!B18,'Data Sheet'!B21:B22)-1*'Data Sheet'!B19,0) -> 18380 | D8: =IFERROR(SUM('Data Sheet'!C18,'Data Sheet'!C21:C22)-1*'Data Sheet'!C19,0) -> 19019 | E8: =IFERROR(SUM('Data Sheet'!D18,'Data Sheet'!D21:D22)-1*'Data Sheet'!D19,0) -> 20773 | F8: =IFERROR(SUM('Data Sheet'!E18,'Data Sheet'!E21:E22)-1*'Data Sheet'!E19,0) -> 20315 | G8: =IFERROR(SUM('Data Sheet'!F18,'Data Sheet'!F21:F22)-1*'Data Sheet'!F19,0) -> 24962 | H8: =IFERROR(SUM('Data Sheet'!G18,'Data Sheet'!G21:G22)-1*'Data Sheet'!G19,0) -> 28748 | I8: =IFERROR(SUM('Data Sheet'!H18,'Data Sheet'!H21:H22)-1*'Data Sheet'!H19,0) -> 34997 | J8: =IFERROR(SUM('Data Sheet'!I18,'Data Sheet'!I21:I22)-1*'Data Sheet'!I19,0) -> 33205 | ... L8: =IFERROR(SUM('Data Sheet'!K18,'Data Sheet'!K21:K22)-1*'Data Sheet'!K19,0) -> 35208
B9: COGS % Sales | C9: =C8/C5 -> 0.55424884 | D9: =D8/D5 -> 0.53506822 | E9: =E8/E5 -> 0.5284406 | F9: =F8/F5 -> 0.51064525 | G9: =G8/G5 -> 0.53079017 | H9: =H8/H5 -> 0.54814476 | I9: =I8/I5 -> 0.57769891 | J9: =J8/J5 -> 0.53646439 | ... L9: =L8/L5 -> 0.54613141
B11: Gross Profit | C11: =C5-C8 -> 14782 | D11: =D5-D8 -> 16526 | E11: =E5-E8 -> 18537 | F11: =F5-F8 -> 19468 | G11: =G5-G8 -> 22066 | H11: =H5-H8 -> 23698 | I11: =I5-I8 -> 25583 | J11: =J5-J8 -> 28691 | ... L11: =L5-L8 -> 29260
B12: Gross Margin % | C12: =C11/C5 -> 0.44575116 | D12: =D11/D5 -> 0.46493178 | E12: =E11/E5 -> 0.4715594 | F12: =F11/F5 -> 0.48935475 | G12: =G11/G5 -> 0.46920983 | H12: =H11/H5 -> 0.45185524 | I12: =I11/I5 -> 0.42230109 | J12: =J11/J5 -> 0.46353561 | ... L12: =L11/L5 -> 0.45386859
B14: Selling & Other expenses | C14: =IFERROR(SUM('Data Sheet'!B23:B24),0) -> 8159 | D14: =IFERROR(SUM('Data Sheet'!C23:C24),0) -> 8732 | E14: =IFERROR(SUM('Data Sheet'!D23:D24),0) -> 9349 | F14: =IFERROR(SUM('Data Sheet'!E23:E24),0) -> 9308 | G14: =IFERROR(SUM('Data Sheet'!F23:F24),0) -> 10101 | H14: =IFERROR(SUM('Data Sheet'!G23:G24),0) -> 10523 | I14: =IFERROR(SUM('Data Sheet'!H23:H24),0) -> 11052 | J14: =IFERROR(SUM('Data Sheet'!I23:I24),0) -> 13586 | ... L14: =IFERROR(SUM('Data Sheet'!K23:K24),0) -> 13795
B15: S&G Expenses % Sales | C15: =C14/C5 -> 0.24603462 | D15: =D14/D5 -> 0.24566043 | E15: =E14/E5 -> 0.23782752 | F15: =F14/F5 -> 0.23396928 | G15: =G14/G5 -> 0.21478694 | H15: =H14/H5 -> 0.20064447 | I15: =I14/I5 -> 0.18243645 | J15: =J14/J5 -> 0.21949722 | ... L15: =L14/L5 -> 0.21398213
B17: EBIDTA | C17: =C11-C14 -> 6623 | D17: =D11-D14 -> 7794 | E17: =E11-E14 -> 9188 | F17: =F11-F14 -> 10160 | G17: =G11-G14 -> 11965 | H17: =H11-H14 -> 13175 | I17: =I11-I14 -> 14531 | J17: =J11-J14 -> 15105 | ... L17: =L11-L14 -> 15465
B18: EBIDTA Margins | C18: =C17/C5 -> 0.19971654 | D18: =D17/D5 -> 0.21927135 | E18: =E17/E5 -> 0.23373187 | F18: =F17/F5 -> 0.25538547 | G18: =G17/G5 -> 0.2544229 | H18: =H17/H5 -> 0.25121077 | I18: =I17/I5 -> 0.23986464 | J18: =J17/J5 -> 0.24403839 | ... L18: =L17/L5 -> 0.23988646
B20: Interest | C20: =IFERROR('Data Sheet'!B27,0) -> 35 | D20: =IFERROR('Data Sheet'!C27,0) -> 26 | E20: =IFERROR('Data Sheet'!D27,0) -> 33 | F20: =IFERROR('Data Sheet'!E27,0) -> 118 | G20: =IFERROR('Data Sheet'!F27,0) -> 117 | H20: =IFERROR('Data Sheet'!G27,0) -> 106 | I20: =IFERROR('Data Sheet'!H27,0) -> 114 | J20: =IFERROR('Data Sheet'!I27,0) -> 334 | ... L20: =IFERROR('Data Sheet'!K27,0) -> 410
B21: Interest % Sales | C21: =C20/C5 -> 0.0010554249 | D21: =D20/D5 -> 0.00073146715 | E21: =E20/E5 -> 0.00083948105 | F21: =F20/F5 -> 0.002966091 | G21: =G20/G5 -> 0.0024878796 | H21: =H20/H5 -> 0.0020211265 | I21: =I20/I5 -> 0.0018818092 | J21: =J20/J5 -> 0.0053961484 | ... L21: =L20/L5 -> 0.0063597444
B23: Depreciation | C23: =IFERROR('Data Sheet'!B26,0) -> 432 | D23: =IFERROR('Data Sheet'!C26,0) -> 520 | E23: =IFERROR('Data Sheet'!D26,0) -> 565 | F23: =IFERROR('Data Sheet'!E26,0) -> 1002 | G23: =IFERROR('Data Sheet'!F26,0) -> 1074 | H23: =IFERROR('Data Sheet'!G26,0) -> 1091 | I23: =IFERROR('Data Sheet'!H26,0) -> 1137 | J23: =IFERROR('Data Sheet'!I26,0) -> 1216 | ... L23: =IFERROR('Data Sheet'!K26,0) -> 1333
B24: Depreciation % Sales | C24: =C23/C5 -> 0.013026959 | D24: =D23/D5 -> 0.014629343 | E24: =E23/E5 -> 0.014372933 | F24: =F23/F5 -> 0.025186638 | G24: =G23/G5 -> 0.022837459 | H24: =H23/H5 -> 0.020802349 | I24: =I23/I5 -> 0.01876857 | J24: =J23/J5 -> 0.019645858 | ... L24: =L23/L5 -> 0.020676925
B26: EBIT | C26: =C29+C20 -> 6191 | D26: =D29+D20 -> 7274 | E26: =E29+E20 -> 8623 | F26: =F29+F20 -> 9158 | G26: =G29+G20 -> 10891 | H26: =H29+H20 -> 12084 | I26: =I29+I20 -> 13394 | J26: =J29+J20 -> 13889 | ... L26: =L29+L20 -> 14132
B27: EBIT % Sales | C27: =C26/C5 -> 0.18668958 | D27: =D26/D5 -> 0.204642 | E27: =E26/E5 -> 0.21935894 | F27: =F26/F5 -> 0.23019883 | G27: =G26/G5 -> 0.23158544 | H27: =H26/H5 -> 0.23040842 | I27: =I26/I5 -> 0.22109607 | J27: =J26/J5 -> 0.22439253 | ... L27: =L26/L5 -> 0.21920953
B29: EBT | C29: =C17-SUM(C20,C23) -> 6156 | D29: =D17-SUM(D20,D23) -> 7248 | E29: =E17-SUM(E20,E23) -> 8590 | F29: =F17-SUM(F20,F23) -> 9040 | G29: =G17-SUM(G20,G23) -> 10774 | H29: =H17-SUM(H20,H23) -> 11978 | I29: =I17-SUM(I20,I23) -> 13280 | J29: =J17-SUM(J20,J23) -> 13555 | ... L29: =L17-SUM(L20,L23) -> 13722
B30: EBT % Sales | C30: =C29/C5 -> 0.18563416 | D30: =D29/D5 -> 0.20391054 | E30: =E29/E5 -> 0.21851946 | F30: =F29/F5 -> 0.22723274 | G30: =G29/G5 -> 0.22909756 | H30: =H29/H5 -> 0.22838729 | I30: =I29/I5 -> 0.21921426 | J30: =J29/J5 -> 0.21899638 | ... L30: =L29/L5 -> 0.21284979
B32: Taxes | C32: =IFERROR('Data Sheet'!B29,0) -> 1977 | D32: =IFERROR('Data Sheet'!C29,0) -> 2079 | E32: =IFERROR('Data Sheet'!D29,0) -> 2544 | F32: =IFERROR('Data Sheet'!E29,0) -> 2409 | G32: =IFERROR('Data Sheet'!F29,0) -> 2606 | H32: =IFERROR('Data Sheet'!G29,0) -> 2987 | I32: =IFERROR('Data Sheet'!H29,0) -> 3201 | J32: =IFERROR('Data Sheet'!I29,0) -> 3644 | ... L32: =IFERROR('Data Sheet'!K29,0) -> 3160
B33: Effective tax rate | C33: =C32/C29 -> 0.3211501 | D33: =D32/D29 -> 0.28683775 | E33: =E32/E29 -> 0.29615832 | F33: =F32/F29 -> 0.2664823 | G33: =G32/G29 -> 0.2418786 | H33: =H32/H29 -> 0.24937385 | I33: =I32/I29 -> 0.24103916 | J33: =J32/J29 -> 0.26883069 | ... L33: =L32/L29 -> 0.23028713
B35: Net Profit | C35: =C29-C32 -> 4179 | D35: =D29-D32 -> 5169 | E35: =E29-E32 -> 6046 | F35: =F29-F32 -> 6631 | G35: =G29-G32 -> 8168 | H35: =H29-H32 -> 8991 | I35: =I29-I32 -> 10079 | J35: =J29-J32 -> 9911 | ... L35: =L29-L32 -> 10562
B36: Net Margins | C36: =C35/C5 -> 0.12601773 | D36: =D35/D5 -> 0.1454213 | E36: =E35/E5 -> 0.1538031 | F36: =F35/F5 -> 0.16667923 | G36: =G35/G5 -> 0.17368376 | H36: =H35/H5 -> 0.17143347 | I36: =I35/I5 -> 0.16637504 | J36: =J35/J5 -> 0.16012343 | ... L36: =L35/L5 -> 0.16383322
B38: No of Equity Shares | C38: =IFERROR('Data Sheet'!B93,0) -> 216.43 | D38: =IFERROR('Data Sheet'!C93,0) -> 216.45 | E38: =IFERROR('Data Sheet'!D93,0) -> 216.47 | F38: =IFERROR('Data Sheet'!E93,0) -> 216.48 | G38: =IFERROR('Data Sheet'!F93,0) -> 234.96 | H38: =IFERROR('Data Sheet'!G93,0) -> 234.96 | I38: =IFERROR('Data Sheet'!H93,0) -> 234.96 | J38: =IFERROR('Data Sheet'!I93,0) -> 234.96 | ... L38: =IFERROR('Data Sheet'!K93,0) -> 234.96
B40: EPS | C40: =IFERROR(C35/C38,0) -> 19.308783 | D40: =IFERROR(D35/D38,0) -> 23.880804 | E40: =IFERROR(E35/E38,0) -> 27.929967 | F40: =IFERROR(F35/F38,0) -> 30.631005 | G40: =IFERROR(G35/G38,0) -> 34.763364 | H40: =IFERROR(H35/H38,0) -> 38.266088 | I40: =IFERROR(I35/I38,0) -> 42.896663 | J40: =IFERROR(J35/J38,0) -> 42.181648 | ... L40: =IFERROR(L35/L38,0) -> 44.952332
B41: EPS Growth % | D41: =IFERROR(D40/C40-1,0) -> 0.23678449 | E41: =IFERROR(E40/D40-1,0) -> 0.16955725 | F41: =IFERROR(F40/E40-1,0) -> 0.096707524 | G41: =IFERROR(G40/F40-1,0) -> 0.13490771 | H41: =IFERROR(H40/G40-1,0) -> 0.10075906 | I41: =IFERROR(I40/H40-1,0) -> 0.1210099 | J41: =IFERROR(J40/I40-1,0) -> -0.01666832 | K41: =IFERROR(K40/J40-1,0) -> -0.019372414 | L41: =IFERROR(L40/K40-1,0) -> 0.086737319
B43: DPS | C43: =IFERROR('Data Sheet'!B31/'Historical FS'!C38,0) -> 16.966225 | D43: =IFERROR('Data Sheet'!C31/'Historical FS'!D38,0) -> 19.95842 | E43: =IFERROR('Data Sheet'!D31/'Historical FS'!E38,0) -> 21.952234 | F43: =IFERROR('Data Sheet'!E31/'Historical FS'!F38,0) -> 24.944568 | G43: =IFERROR('Data Sheet'!F31/'Historical FS'!G38,0) -> 40.506895 | H43: =IFERROR('Data Sheet'!G31/'Historical FS'!H38,0) -> 34.005788 | I43: =IFERROR('Data Sheet'!H31/'Historical FS'!I38,0) -> 39.006639 | J43: =IFERROR('Data Sheet'!I31/'Historical FS'!J38,0) -> 42.00715 | ... L43: =IFERROR('Data Sheet'!K31/'Historical FS'!L38,0) -> 41.00698
B44: Dividend Payout ratio | C44: =IFERROR(C43/C40,0) -> 0.87867911 | D44: =IFERROR(D43/D40,0) -> 0.8357516 | E44: =IFERROR(E43/E40,0) -> 0.7859742 | F44: =IFERROR(F43/F40,0) -> 0.81435681 | G44: =IFERROR(G43/G40,0) -> 1.1652179 | H44: =IFERROR(H43/H40,0) -> 0.88866644 | I44: =IFERROR(I43/I40,0) -> 0.9093164 | J44: =IFERROR(J43/J40,0) -> 0.99586318 | ... L44: =IFERROR(L43/L40,0) -> 0.91223253
B46: Retained Earnings | C46: =IFERROR(IF(C40>C43,1-C44,0),0) -> 0.12132089 | D46: =IFERROR(IF(D40>D43,1-D44,0),0) -> 0.1642484 | E46: =IFERROR(IF(E40>E43,1-E44,0),0) -> 0.2140258 | F46: =IFERROR(IF(F40>F43,1-F44,0),0) -> 0.18564319 | G46: =IFERROR(IF(G40>G43,1-G44,0),0) -> 0 | H46: =IFERROR(IF(H40>H43,1-H44,0),0) -> 0.11133356 | I46: =IFERROR(IF(I40>I43,1-I44,0),0) -> 0.0906836 | J46: =IFERROR(IF(J40>J43,1-J44,0),0) -> 0.0041368177 | ... L46: =IFERROR(IF(L40>L43,1-L44,0),0) -> 0.087767468
A48: # | B48: Balance sheet
B49: Equity Share Capital | C49: =IFERROR('Data Sheet'!B57,0) -> 216 | D49: =IFERROR('Data Sheet'!C57,0) -> 216 | E49: =IFERROR('Data Sheet'!D57,0) -> 216 | F49: =IFERROR('Data Sheet'!E57,0) -> 216 | G49: =IFERROR('Data Sheet'!F57,0) -> 235 | H49: =IFERROR('Data Sheet'!G57,0) -> 235 | I49: =IFERROR('Data Sheet'!H57,0) -> 235 | J49: =IFERROR('Data Sheet'!I57,0) -> 235 | ... L49: =IFERROR('Data Sheet'!K57,0) -> 235
B50: Reserves | C50: =IFERROR('Data Sheet'!B58,0) -> 6528 | D50: =IFERROR('Data Sheet'!C58,0) -> 7065 | E50: =IFERROR('Data Sheet'!D58,0) -> 7651 | F50: =IFERROR('Data Sheet'!E58,0) -> 8013 | G50: =IFERROR('Data Sheet'!F58,0) -> 47439 | H50: =IFERROR('Data Sheet'!G58,0) -> 48826 | I50: =IFERROR('Data Sheet'!H58,0) -> 50069 | J50: =IFERROR('Data Sheet'!I58,0) -> 50983 | ... L50: =IFERROR('Data Sheet'!K58,0) -> 48504
B51: Borrowings | C51: =IFERROR('Data Sheet'!B59,0) -> 277 | D51: =IFERROR('Data Sheet'!C59,0) -> 0 | E51: =IFERROR('Data Sheet'!D59,0) -> 99 | F51: =IFERROR('Data Sheet'!E59,0) -> 0 | G51: =IFERROR('Data Sheet'!F59,0) -> 0 | H51: =IFERROR('Data Sheet'!G59,0) -> 1043 | I51: =IFERROR('Data Sheet'!H59,0) -> 1219 | J51: =IFERROR('Data Sheet'!I59,0) -> 1484 | ... L51: =IFERROR('Data Sheet'!K59,0) -> 1478
B52: Other Liabilities | C52: =IFERROR('Data Sheet'!B60,0) -> 8685 | D52: =IFERROR('Data Sheet'!C60,0) -> 10581 | E52: =IFERROR('Data Sheet'!D60,0) -> 10663 | F52: =IFERROR('Data Sheet'!E60,0) -> 11924 | G52: =IFERROR('Data Sheet'!F60,0) -> 21066 | H52: =IFERROR('Data Sheet'!G60,0) -> 20402 | I52: =IFERROR('Data Sheet'!H60,0) -> 21554 | J52: =IFERROR('Data Sheet'!I60,0) -> 25787 | ... L52: =IFERROR('Data Sheet'!K60,0) -> 29521
B53: Total Liabilities | C53: =IFERROR('Data Sheet'!B66,0) -> 15706 | D53: =IFERROR('Data Sheet'!C66,0) -> 17862 | E53: =IFERROR('Data Sheet'!D66,0) -> 18629 | F53: =IFERROR('Data Sheet'!E66,0) -> 20153 | G53: =IFERROR('Data Sheet'!F66,0) -> 68740 | H53: =IFERROR('Data Sheet'!G66,0) -> 70506 | I53: =IFERROR('Data Sheet'!H66,0) -> 73077 | J53: =IFERROR('Data Sheet'!I66,0) -> 78489 | ... L53: =IFERROR('Data Sheet'!K66,0) -> 79738
B55: Fixed Assets Net Block | C55: =IFERROR('Data Sheet'!B62,0) -> 4419 | D55: =IFERROR('Data Sheet'!C62,0) -> 4528 | E55: =IFERROR('Data Sheet'!D62,0) -> 4715 | F55: =IFERROR('Data Sheet'!E62,0) -> 5479 | G55: =IFERROR('Data Sheet'!F62,0) -> 51443 | H55: =IFERROR('Data Sheet'!G62,0) -> 51473 | I55: =IFERROR('Data Sheet'!H62,0) -> 52678 | J55: =IFERROR('Data Sheet'!I62,0) -> 53744 | ... L55: =IFERROR('Data Sheet'!K62,0) -> 57428
B56: Capital Work in Progress | C56: =IFERROR('Data Sheet'!B63,0) -> 229 | D56: =IFERROR('Data Sheet'!C63,0) -> 461 | E56: =IFERROR('Data Sheet'!D63,0) -> 406 | F56: =IFERROR('Data Sheet'!E63,0) -> 597 | G56: =IFERROR('Data Sheet'!F63,0) -> 745 | H56: =IFERROR('Data Sheet'!G63,0) -> 1313 | I56: =IFERROR('Data Sheet'!H63,0) -> 1132 | J56: =IFERROR('Data Sheet'!I63,0) -> 1025 | ... L56: =IFERROR('Data Sheet'!K63,0) -> 880
B57: Investments | C57: =IFERROR('Data Sheet'!B64,0) -> 3794 | D57: =IFERROR('Data Sheet'!C64,0) -> 2873 | E57: =IFERROR('Data Sheet'!D64,0) -> 2716 | F57: =IFERROR('Data Sheet'!E64,0) -> 1255 | G57: =IFERROR('Data Sheet'!F64,0) -> 2709 | H57: =IFERROR('Data Sheet'!G64,0) -> 3521 | I57: =IFERROR('Data Sheet'!H64,0) -> 2882 | J57: =IFERROR('Data Sheet'!I64,0) -> 4625 | ... L57: =IFERROR('Data Sheet'!K64,0) -> 4359
...

Sheet Financial Ratios
B2: ="Ratio Analysis - "& 'Data Sheet'!B1 -> Ratio Analysis - HINDUSTAN UNILEVER LTD
B3: Years | C3: ='[1]Data Sheet'!B16 -> 42825 | D3: ='[1]Data Sheet'!C16 -> 43190 | E3: ='[1]Data Sheet'!D16 -> 43555 | F3: ='[1]Data Sheet'!E16 -> 43921 | G3: ='[1]Data Sheet'!F16 -> 44286 | H3: ='[1]Data Sheet'!G16 -> 44651 | I3: ='[1]Data Sheet'!H16 -> 45016 | J3: ='[1]Data Sheet'!I16 -> 45382 | ... L3: ='[1]Data Sheet'!K16 -> 46112 | M3: Trend | N3: Mean | O3: Median
B5: SalesGrowth | D5: =IFERROR('Historical FS'!D6,0) -> 0.071859357 | E5: =IFERROR('Historical FS'!E6,0) -> 0.10592207 | F5: =IFERROR('Historical FS'!F6,0) -> 0.012032562 | G5: =IFERROR('Historical FS'!G6,0) -> 0.18211296 | H5: =IFERROR('Historical FS'!H6,0) -> 0.11520796 | I5: =IFERROR('Historical FS'!I6,0) -> 0.15509286 | J5: =IFERROR('Historical FS'!J6,0) -> 0.021723341 | K5: =IFERROR('Historical FS'!K6,0) -> -0.0091766835 | L5: =IFERROR('Historical FS'!L6,0) -> 0.051200104 | N5: =IFERROR(AVERAGE(D5:L5),0) -> 0.078441615 | O5: =IFERROR(MEDIAN(D5:L5),0) -> 0.071859357
B6: EBITDA Growth | D6: =IFERROR('Historical FS'!D17/'Historical FS'!C17-1,0) -> 0.17680809 | E6: =IFERROR('Historical FS'!E17/'Historical FS'!D17-1,0) -> 0.17885553 | F6: =IFERROR('Historical FS'!F17/'Historical FS'!E17-1,0) -> 0.10579016 | G6: =IFERROR('Historical FS'!G17/'Historical FS'!F17-1,0) -> 0.17765748 | H6: =IFERROR('Historical FS'!H17/'Historical FS'!G17-1,0) -> 0.10112829 | I6: =IFERROR('Historical FS'!I17/'Historical FS'!H17-1,0) -> 0.1029222 | J6: =IFERROR('Historical FS'!J17/'Historical FS'!I17-1,0) -> 0.039501755 | K6: =IFERROR('Historical FS'!K17/'Historical FS'!J17-1,0) -> -0.00026481298 | L6: =IFERROR('Historical FS'!L17/'Historical FS'!K17-1,0) -> 0.024104364 | N6: =IFERROR(AVERAGE(D6:L6),0) -> 0.10072256 | O6: =IFERROR(MEDIAN(D6:L6),0) -> 0.1029222
B7: EBIT Growth | D7: =IFERROR('Historical FS'!D26/'Historical FS'!C26-1,0) -> 0.17493135 | E7: =IFERROR('Historical FS'!E26/'Historical FS'!D26-1,0) -> 0.18545505 | F7: =IFERROR('Historical FS'!F26/'Historical FS'!E26-1,0) -> 0.062043372 | G7: =IFERROR('Historical FS'!G26/'Historical FS'!F26-1,0) -> 0.18923346 | H7: =IFERROR('Historical FS'!H26/'Historical FS'!G26-1,0) -> 0.10953999 | I7: =IFERROR('Historical FS'!I26/'Historical FS'!H26-1,0) -> 0.10840781 | J7: =IFERROR('Historical FS'!J26/'Historical FS'!I26-1,0) -> 0.036956846 | K7: =IFERROR('Historical FS'!K26/'Historical FS'!J26-1,0) -> -0.0029519764 | L7: =IFERROR('Historical FS'!L26/'Historical FS'!K26-1,0) -> 0.020508377 | N7: =IFERROR(AVERAGE(D7:L7),0) -> 0.09823603 | O7: =IFERROR(MEDIAN(D7:L7),0) -> 0.10840781
B8: Net Profit Growth | D8: =IFERROR('Historical FS'!D35/'Historical FS'!C35-1,0) -> 0.23689878 | E8: =IFERROR('Historical FS'!E35/'Historical FS'!D35-1,0) -> 0.16966531 | F8: =IFERROR('Historical FS'!F35/'Historical FS'!E35-1,0) -> 0.096758187 | G8: =IFERROR('Historical FS'!G35/'Historical FS'!F35-1,0) -> 0.23179008 | H8: =IFERROR('Historical FS'!H35/'Historical FS'!G35-1,0) -> 0.10075906 | I8: =IFERROR('Historical FS'!I35/'Historical FS'!H35-1,0) -> 0.1210099 | J8: =IFERROR('Historical FS'!J35/'Historical FS'!I35-1,0) -> -0.01666832 | K8: =IFERROR('Historical FS'!K35/'Historical FS'!J35-1,0) -> -0.019372414 | L8: =IFERROR('Historical FS'!L35/'Historical FS'!K35-1,0) -> 0.086737319 | N8: =IFERROR(AVERAGE(D8:L8),0) -> 0.1119531 | O8: =IFERROR(MEDIAN(D8:L8),0) -> 0.10075906
B9: Dividend Growth | D9: =IFERROR('Historical FS'!D43/'Historical FS'!C43-1,0) -> 0.17636188 | E9: =IFERROR('Historical FS'!E43/'Historical FS'!D43-1,0) -> 0.099898369 | F9: =IFERROR('Historical FS'!F43/'Historical FS'!E43-1,0) -> 0.13631114 | G9: =IFERROR('Historical FS'!G43/'Historical FS'!F43-1,0) -> 0.6238764 | H9: =IFERROR('Historical FS'!H43/'Historical FS'!G43-1,0) -> -0.16049383 | I9: =IFERROR('Historical FS'!I43/'Historical FS'!H43-1,0) -> 0.14705882 | J9: =IFERROR('Historical FS'!J43/'Historical FS'!I43-1,0) -> 0.076923077 | K9: =IFERROR('Historical FS'!K43/'Historical FS'!J43-1,0) -> 0.26190476 | L9: =IFERROR('Historical FS'!L43/'Historical FS'!K43-1,0) -> -0.22641509 | N9: =IFERROR(AVERAGE(D9:L9),0) -> 0.12615839 | O9: =IFERROR(MEDIAN(D9:L9),0) -> 0.13631114
B11: Gross Margin | C11: =IFERROR('Historical FS'!C12,0) -> 0.44575116 | D11: =IFERROR('Historical FS'!D12,0) -> 0.46493178 | E11: =IFERROR('Historical FS'!E12,0) -> 0.4715594 | F11: =IFERROR('Historical FS'!F12,0) -> 0.48935475 | G11: =IFERROR('Historical FS'!G12,0) -> 0.46920983 | H11: =IFERROR('Historical FS'!H12,0) -> 0.45185524 | I11: =IFERROR('Historical FS'!I12,0) -> 0.42230109 | J11: =IFERROR('Historical FS'!J12,0) -> 0.46353561 | ... L11: =IFERROR('Historical FS'!L12,0) -> 0.45386859 | N11: =IFERROR(AVERAGE(C11:L11),0) -> 0.45923857 | O11: =IFERROR(MEDIAN(C11:L11),0) -> 0.46177694
B12: EBITDA Margin | C12: =IFERROR('Historical FS'!C18,0) -> 0.19971654 | D12: =IFERROR('Historical FS'!D18,0) -> 0.21927135 | E12: =IFERROR('Historical FS'!E18,0) -> 0.23373187 | F12: =IFERROR('Historical FS'!F18,0) -> 0.25538547 | G12: =IFERROR('Historical FS'!G18,0) -> 0.2544229 | H12: =IFERROR('Historical FS'!H18,0) -> 0.25121077 | I12: =IFERROR('Historical FS'!I18,0) -> 0.23986464 | J12: =IFERROR('Historical FS'!J18,0) -> 0.24403839 | ... L12: =IFERROR('Historical FS'!L18,0) -> 0.23988646 | N12: =IFERROR(AVERAGE(C12:L12),0) -> 0.23837617 | O12: =IFERROR(MEDIAN(C12:L12),0) -> 0.24196242
B13: EBIT Margin | C13: =IFERROR('Historical FS'!C27,0) -> 0.18668958 | D13: =IFERROR('Historical FS'!D27,0) -> 0.204642 | E13: =IFERROR('Historical FS'!E27,0) -> 0.21935894 | F13: =IFERROR('Historical FS'!F27,0) -> 0.23019883 | G13: =IFERROR('Historical FS'!G27,0) -> 0.23158544 | H13: =IFERROR('Historical FS'!H27,0) -> 0.23040842 | I13: =IFERROR('Historical FS'!I27,0) -> 0.22109607 | J13: =IFERROR('Historical FS'!J27,0) -> 0.22439253 | ... L13: =IFERROR('Historical FS'!L27,0) -> 0.21920953 | N13: =IFERROR(AVERAGE(C13:L13),0) -> 0.21933836 | O13: =IFERROR(MEDIAN(C13:L13),0) -> 0.2227443
B14: EBT Margin | C14: =IFERROR('Historical FS'!C30,0) -> 0.18563416 | D14: =IFERROR('Historical FS'!D30,0) -> 0.20391054 | E14: =IFERROR('Historical FS'!E30,0) -> 0.21851946 | F14: =IFERROR('Historical FS'!F30,0) -> 0.22723274 | G14: =IFERROR('Historical FS'!G30,0) -> 0.22909756 | H14: =IFERROR('Historical FS'!H30,0) -> 0.22838729 | I14: =IFERROR('Historical FS'!I30,0) -> 0.21921426 | J14: =IFERROR('Historical FS'!J30,0) -> 0.21899638 | ... L14: =IFERROR('Historical FS'!L30,0) -> 0.21284979 | N14: =IFERROR(AVERAGE(C14:L14),0) -> 0.21634319 | O14: =IFERROR(MEDIAN(C14:L14),0) -> 0.21910532
B15: Net Profit Margin | C15: =IFERROR('Historical FS'!C36,0) -> 0.12601773 | D15: =IFERROR('Historical FS'!D36,0) -> 0.1454213 | E15: =IFERROR('Historical FS'!E36,0) -> 0.1538031 | F15: =IFERROR('Historical FS'!F36,0) -> 0.16667923 | G15: =IFERROR('Historical FS'!G36,0) -> 0.17368376 | H15: =IFERROR('Historical FS'!H36,0) -> 0.17143347 | I15: =IFERROR('Historical FS'!I36,0) -> 0.16637504 | J15: =IFERROR('Historical FS'!J36,0) -> 0.16012343 | ... L15: =IFERROR('Historical FS'!L36,0) -> 0.16383322 | N15: =IFERROR(AVERAGE(C15:L15),0) -> 0.1585846 | O15: =IFERROR(MEDIAN(C15:L15),0) -> 0.16197833
B17: SalesExpenses%Sales | C17: =IFERROR('Historical FS'!C15,0) -> 0.24603462 | D17: =IFERROR('Historical FS'!D15,0) -> 0.24566043 | E17: =IFERROR('Historical FS'!E15,0) -> 0.23782752 | F17: =IFERROR('Historical FS'!F15,0) -> 0.23396928 | G17: =IFERROR('Historical FS'!G15,0) -> 0.21478694 | H17: =IFERROR('Historical FS'!H15,0) -> 0.20064447 | I17: =IFERROR('Historical FS'!I15,0) -> 0.18243645 | J17: =IFERROR('Historical FS'!J15,0) -> 0.21949722 | ... L17: =IFERROR('Historical FS'!L15,0) -> 0.21398213 | N17: =IFERROR(AVERAGE(C17:L17),0) -> 0.2208624 | O17: =IFERROR(MEDIAN(C17:L17),0) -> 0.21714208
B18: Depreciation%Sales | C18: =IFERROR('Historical FS'!C24,0) -> 0.013026959 | D18: =IFERROR('Historical FS'!D24,0) -> 0.014629343 | E18: =IFERROR('Historical FS'!E24,0) -> 0.014372933 | F18: =IFERROR('Historical FS'!F24,0) -> 0.025186638 | G18: =IFERROR('Historical FS'!G24,0) -> 0.022837459 | H18: =IFERROR('Historical FS'!H24,0) -> 0.020802349 | I18: =IFERROR('Historical FS'!I24,0) -> 0.01876857 | J18: =IFERROR('Historical FS'!J24,0) -> 0.019645858 | ... L18: =IFERROR('Historical FS'!L24,0) -> 0.020676925 | N18: =IFERROR(AVERAGE(C18:L18),0) -> 0.019037816 | O18: =IFERROR(MEDIAN(C18:L18),0) -> 0.020038491
B19: OperatingIncome%Sales | C19: =C13 -> 0.18668958 | D19: =D13 -> 0.204642 | E19: =E13 -> 0.21935894 | F19: =F13 -> 0.23019883 | G19: =G13 -> 0.23158544 | H19: =H13 -> 0.23040842 | I19: =I13 -> 0.22109607 | J19: =J13 -> 0.22439253 | ... L19: =L13 -> 0.21920953 | N19: =IFERROR(AVERAGE(C19:L19),0) -> 0.21933836 | O19: =IFERROR(MEDIAN(C19:L19),0) -> 0.2227443
B21: Return on Capital Employed | C21: =IFERROR('Historical FS'!C26/SUM('Historical FS'!C49:C51),0) -> 0.88178322 | D21: =IFERROR('Historical FS'!D26/SUM('Historical FS'!D49:D51),0) -> 0.99903859 | E21: =IFERROR('Historical FS'!E26/SUM('Historical FS'!E49:E51),0) -> 1.0824755 | F21: =IFERROR('Historical FS'!F26/SUM('Historical FS'!F49:F51),0) -> 1.1128934 | G21: =IFERROR('Historical FS'!G26/SUM('Historical FS'!G49:G51),0) -> 0.22844737 | H21: =IFERROR('Historical FS'!H26/SUM('Historical FS'!H49:H51),0) -> 0.24117835 | I21: =IFERROR('Historical FS'!I26/SUM('Historical FS'!I49:I51),0) -> 0.25996157 | J21: =IFERROR('Historical FS'!J26/SUM('Historical FS'!J49:J51),0) -> 0.26353839 | ... L21: =IFERROR('Historical FS'!L26/SUM('Historical FS'!L49:L51),0) -> 0.28141864 | N21: =IFERROR(AVERAGE(C21:L21),0) -> 0.56219985 | O21: =IFERROR(MEDIAN(C21:L21),0) -> 0.27634106
B22: Retained Earnings% | C22: =IFERROR('Historical FS'!C46,0) -> 0.12132089 | D22: =IFERROR('Historical FS'!D46,0) -> 0.1642484 | E22: =IFERROR('Historical FS'!E46,0) -> 0.2140258 | F22: =IFERROR('Historical FS'!F46,0) -> 0.18564319 | G22: =IFERROR('Historical FS'!G46,0) -> 0 | H22: =IFERROR('Historical FS'!H46,0) -> 0.11133356 | I22: =IFERROR('Historical FS'!I46,0) -> 0.0906836 | J22: =IFERROR('Historical FS'!J46,0) -> 0.0041368177 | ... L22: =IFERROR('Historical FS'!L46,0) -> 0.087767468 | N22: =IFERROR(AVERAGE(C22:L22),0) -> 0.097915973 | O22: =IFERROR(MEDIAN(C22:L22),0) -> 0.10100858
B23: Return on Equity% | C23: =IFERROR('Historical FS'!C35/SUM('Historical FS'!C49:C50),0) -> 0.61966192 | D23: =IFERROR('Historical FS'!D35/SUM('Historical FS'!D49:D50),0) -> 0.70992995 | E23: =IFERROR('Historical FS'!E35/SUM('Historical FS'!E49:E50),0) -> 0.76852676 | F23: =IFERROR('Historical FS'!F35/SUM('Historical FS'!F49:F50),0) -> 0.80580873 | G23: =IFERROR('Historical FS'!G35/SUM('Historical FS'!G49:G50),0) -> 0.17133028 | H23: =IFERROR('Historical FS'!H35/SUM('Historical FS'!H49:H50),0) -> 0.18326165 | I23: =IFERROR('Historical FS'!I35/SUM('Historical FS'!I49:I50),0) -> 0.2003618 | J23: =IFERROR('Historical FS'!J35/SUM('Historical FS'!J49:J50),0) -> 0.19350619 | ... L23: =IFERROR('Historical FS'!L35/SUM('Historical FS'!L49:L50),0) -> 0.21670531 | N23: =IFERROR(AVERAGE(C23:L23),0) -> 0.40658255 | O23: =IFERROR(MEDIAN(C23:L23),0) -> 0.20853355
B24: Self Sustained Growth Rate | C24: =IFERROR(C22*C23,0) -> 0.075177936 | D24: =IFERROR(D22*D23,0) -> 0.11660486 | E24: =IFERROR(E22*E23,0) -> 0.16448456 | F24: =IFERROR(F22*F23,0) -> 0.1495929 | G24: =IFERROR(G22*G23,0) -> 0 | H24: =IFERROR(H22*H23,0) -> 0.020403172 | I24: =IFERROR(I22*I23,0) -> 0.018169529 | J24: =IFERROR(J22*J23,0) -> 0.00080049982 | ... L24: =IFERROR(L22*L23,0) -> 0.019019676 | N24: =IFERROR(AVERAGE(C24:L24),0) -> 0.056425313 | O24: =IFERROR(MEDIAN(C24:L24),0) -> 0.019711424
B25: Interest Coverage Ratio | C25: =IFERROR('Historical FS'!C26/'Historical FS'!C20,0) -> 176.88571 | D25: =IFERROR('Historical FS'!D26/'Historical FS'!D20,0) -> 279.76923 | E25: =IFERROR('Historical FS'!E26/'Historical FS'!E20,0) -> 261.30303 | F25: =IFERROR('Historical FS'!F26/'Historical FS'!F20,0) -> 77.610169 | G25: =IFERROR('Historical FS'!G26/'Historical FS'!G20,0) -> 93.08547 | H25: =IFERROR('Historical FS'!H26/'Historical FS'!H20,0) -> 114 | I25: =IFERROR('Historical FS'!I26/'Historical FS'!I20,0) -> 117.49123 | J25: =IFERROR('Historical FS'!J26/'Historical FS'!J20,0) -> 41.583832 | ... L25: =IFERROR('Historical FS'!L26/'Historical FS'!L20,0) -> 34.468293 | N25: =IFERROR(AVERAGE(C25:L25),0) -> 123.25434 | O25: =IFERROR(MEDIAN(C25:L25),0) -> 103.54274
B27: Debtor Turnover Ratio | C27: =IFERROR('Historical FS'!C5/'Historical FS'!C61,0) -> 30.564055 | D27: =IFERROR('Historical FS'!D5/'Historical FS'!D61,0) -> 27.133588 | E27: =IFERROR('Historical FS'!E5/'Historical FS'!E61,0) -> 21.646476 | F27: =IFERROR('Historical FS'!F5/'Historical FS'!F61,0) -> 34.624021 | G27: =IFERROR('Historical FS'!G5/'Historical FS'!G61,0) -> 26.750853 | H27: =IFERROR('Historical FS'!H5/'Historical FS'!H61,0) -> 23.455277 | I27: =IFERROR('Historical FS'!I5/'Historical FS'!I61,0) -> 19.675219 | J27: =IFERROR('Historical FS'!J5/'Historical FS'!J61,0) -> 20.652653 | ... L27: =IFERROR('Historical FS'!L5/'Historical FS'!L61,0) -> 19.079017 | N27: =IFERROR(AVERAGE(C27:L27),0) -> 23.963981 | O27: =IFERROR(MEDIAN(C27:L27),0) -> 22.550877
B28: Creditor Turnover Ratio | C28: =IFERROR('Historical FS'!C5/'Historical FS'!C52,0) -> 3.8183074 | D28: =IFERROR('Historical FS'!D5/'Historical FS'!D52,0) -> 3.3593233 | E28: =IFERROR('Historical FS'!E5/'Historical FS'!E52,0) -> 3.6865798 | F28: =IFERROR('Historical FS'!F5/'Historical FS'!F52,0) -> 3.3363804 | G28: =IFERROR('Historical FS'!G5/'Historical FS'!G52,0) -> 2.2324124 | H28: =IFERROR('Historical FS'!H5/'Historical FS'!H52,0) -> 2.5706303 | I28: =IFERROR('Historical FS'!I5/'Historical FS'!I52,0) -> 2.8106152 | J28: =IFERROR('Historical FS'!J5/'Historical FS'!J52,0) -> 2.4002792 | ... L28: =IFERROR('Historical FS'!L5/'Historical FS'!L52,0) -> 2.1838014 | N28: =IFERROR(AVERAGE(C28:L28),0) -> 2.8526813 | O28: =IFERROR(MEDIAN(C28:L28),0) -> 2.6906228
B29: Inventory Turnover | C29: =IFERROR('Historical FS'!C5/'Historical FS'!C62,0) -> 13.050767 | D29: =IFERROR('Historical FS'!D5/'Historical FS'!D62,0) -> 14.144449 | E29: =IFERROR('Historical FS'!E5/'Historical FS'!E62,0) -> 15.27195 | F29: =IFERROR('Historical FS'!F5/'Historical FS'!F62,0) -> 14.377665 | G29: =IFERROR('Historical FS'!G5/'Historical FS'!G62,0) -> 13.139983 | H29: =IFERROR('Historical FS'!H5/'Historical FS'!H62,0) -> 12.804199 | I29: =IFERROR('Historical FS'!I5/'Historical FS'!I62,0) -> 14.250765 | J29: =IFERROR('Historical FS'!J5/'Historical FS'!J62,0) -> 15.389359 | ... L29: =IFERROR('Historical FS'!L5/'Historical FS'!L62,0) -> 13.461683 | N29: =IFERROR(AVERAGE(C29:L29),0) -> 13.978165 | O29: =IFERROR(MEDIAN(C29:L29),0) -> 14.017638
B30: Fixed Asset Turnover | C30: =IFERROR('Historical FS'!C5/'Historical FS'!C55,0) -> 7.5044128 | D30: =IFERROR('Historical FS'!D5/'Historical FS'!D55,0) -> 7.8500442 | E30: =IFERROR('Historical FS'!E5/'Historical FS'!E55,0) -> 8.3372216 | F30: =IFERROR('Historical FS'!F5/'Historical FS'!F55,0) -> 7.2609965 | G30: =IFERROR('Historical FS'!G5/'Historical FS'!G55,0) -> 0.91417686 | H30: =IFERROR('Historical FS'!H5/'Historical FS'!H55,0) -> 1.0189031 | I30: =IFERROR('Historical FS'!I5/'Historical FS'!I55,0) -> 1.1500057 | J30: =IFERROR('Historical FS'!J5/'Historical FS'!J55,0) -> 1.151682 | ... L30: =IFERROR('Historical FS'!L5/'Historical FS'!L55,0) -> 1.1225883 | N30: =IFERROR(AVERAGE(C30:L30),0) -> 3.7438733 | O30: =IFERROR(MEDIAN(C30:L30),0) -> 1.1508439
B31: Capital Turnover Ratio | C31: =IFERROR('Historical FS'!C5/SUM('Historical FS'!C49:C50),0) -> 4.9172598 | D31: =IFERROR('Historical FS'!D5/SUM('Historical FS'!D49:D50),0) -> 4.8818844 | E31: =IFERROR('Historical FS'!E5/SUM('Historical FS'!E49:E50),0) -> 4.9968222 | F31: =IFERROR('Historical FS'!F5/SUM('Historical FS'!F49:F50),0) -> 4.8344878 | G31: =IFERROR('Historical FS'!G5/SUM('Historical FS'!G49:G50),0) -> 0.98644964 | H31: =IFERROR('Historical FS'!H5/SUM('Historical FS'!H49:H50),0) -> 1.0689957 | I31: =IFERROR('Historical FS'!I5/SUM('Historical FS'!I49:I50),0) -> 1.204278 | J31: =IFERROR('Historical FS'!J5/SUM('Historical FS'!J49:J50),0) -> 1.2084814 | ... L31: =IFERROR('Historical FS'!L5/SUM('Historical FS'!L49:L50),0) -> 1.322719 | N31: =IFERROR(AVERAGE(C31:L31),0) -> 2.6662785 | O31: =IFERROR(MEDIAN(C31:L31),0) -> 1.2820631
B33: Debtor Days | C33: =365/C27 -> 11.942133 | D33: =365/D27 -> 13.451962 | E33: =365/E27 -> 16.861867 | F33: =365/F27 -> 10.541814 | G33: =365/G27 -> 13.644425 | H33: =365/H27 -> 15.56153 | I33: =365/I27 -> 18.551255 | J33: =365/J27 -> 17.673275 | ... L33: =365/L27 -> 19.130964 | N33: =IFERROR(AVERAGE(C33:L33),0) -> 16.00884 | O33: =IFERROR(MEDIAN(C33:L33),0) -> 16.211699
B34: Payable Days | C34: =365/C28 -> 95.592093 | D34: =365/D28 -> 108.65283 | E34: =365/E28 -> 99.007759 | F34: =365/F28 -> 109.39999 | G34: =365/G28 -> 163.50026 | H34: =365/H28 -> 141.98852 | I34: =365/I28 -> 129.86481 | J34: =365/J28 -> 152.06564 | ... L34: =365/L28 -> 167.13974 | N34: =IFERROR(AVERAGE(C34:L34),0) -> 133.86952 | O34: =IFERROR(MEDIAN(C34:L34),0) -> 135.92666
B35: Inventory Days | C35: =365/C29 -> 27.967704 | D35: =365/D29 -> 25.805177 | E35: =365/E29 -> 23.900025 | F35: =365/F29 -> 25.386597 | G35: =365/G29 -> 27.777813 | H35: =365/H29 -> 28.506273 | I35: =365/I29 -> 25.612661 | J35: =365/J29 -> 23.717688 | ... L35: =365/L29 -> 27.113995 | N35: =IFERROR(AVERAGE(C35:L35),0) -> 26.206427 | O35: =IFERROR(MEDIAN(C35:L35),0) -> 26.040755
B36: Cash Conversion Cycle (in days) | C36: =SUM(C33,C35)-C34 -> -55.682257 | D36: =SUM(D33,D35)-D34 -> -69.395696 | E36: =SUM(E33,E35)-E34 -> -58.245866 | F36: =SUM(F33,F35)-F34 -> -73.471583 | G36: =SUM(G33,G35)-G34 -> -122.07802 | H36: =SUM(H33,H35)-H34 -> -97.920718 | I36: =SUM(I33,I35)-I34 -> -85.700891 | J36: =SUM(J33,J35)-J34 -> -110.67468 | ... L36: =SUM(L33,L35)-L34 -> -120.89479 | N36: =IFERROR(AVERAGE(C36:L36),0) -> -91.654256 | O36: =IFERROR(MEDIAN(C36:L36),0) -> -91.810805
B38: CFO/Sales | C38: =IFERROR('Historical FS'!C82/'Historical FS'!C5,0) -> 0.15635366 | D38: =IFERROR('Historical FS'!D82/'Historical FS'!D5,0) -> 0.17045998 | E38: =IFERROR('Historical FS'!E82/'Historical FS'!E5,0) -> 0.14754515 | F38: =IFERROR('Historical FS'!F82/'Historical FS'!F5,0) -> 0.19161451 | G38: =IFERROR('Historical FS'!G82/'Historical FS'!G5,0) -> 0.19484137 | H38: =IFERROR('Historical FS'!H82/'Historical FS'!H5,0) -> 0.17252031 | I38: =IFERROR('Historical FS'!I82/'Historical FS'!I5,0) -> 0.16492242 | J38: =IFERROR('Historical FS'!J82/'Historical FS'!J5,0) -> 0.24991922 | ... L38: =IFERROR('Historical FS'!L82/'Historical FS'!L5,0) -> 0.17061178 | N38: =IFERROR(AVERAGE(C38:L38),0) -> 0.18125987 | O38: =IFERROR(MEDIAN(C38:L38),0) -> 0.17156604
B39: CFO/Total Assets | C39: =IFERROR('Historical FS'!C82/'Historical FS'!C66,0) -> 0.33012861 | D39: =IFERROR('Historical FS'!D82/'Historical FS'!D66,0) -> 0.33921173 | E39: =IFERROR('Historical FS'!E82/'Historical FS'!E66,0) -> 0.31134253 | F39: =IFERROR('Historical FS'!F82/'Historical FS'!F66,0) -> 0.37825634 | G39: =IFERROR('Historical FS'!G82/'Historical FS'!G66,0) -> 0.13329939 | H39: =IFERROR('Historical FS'!H82/'Historical FS'!H66,0) -> 0.1283295 | I39: =IFERROR('Historical FS'!I82/'Historical FS'!I66,0) -> 0.1367188 | J39: =IFERROR('Historical FS'!J82/'Historical FS'!J66,0) -> 0.19708494 | ... L39: =IFERROR('Historical FS'!L82/'Historical FS'!L66,0) -> 0.13793925 | N39: =IFERROR(AVERAGE(C39:L39),0) -> 0.2241141 | O39: =IFERROR(MEDIAN(C39:L39),0) -> 0.17295741
B40: CFO/Total Debt | C40: =IFERROR('Historical FS'!C82/'Historical FS'!C51,0) -> 18.718412 | D40: =IFERROR('Historical FS'!D82/'Historical FS'!D51,0) -> 0 | E40: =IFERROR('Historical FS'!E82/'Historical FS'!E51,0) -> 58.585859 | F40: =IFERROR('Historical FS'!F82/'Historical FS'!F51,0) -> 0 | G40: =IFERROR('Historical FS'!G82/'Historical FS'!G51,0) -> 0 | H40: =IFERROR('Historical FS'!H82/'Historical FS'!H51,0) -> 8.674976 | I40: =IFERROR('Historical FS'!I82/'Historical FS'!I51,0) -> 8.1960623 | J40: =IFERROR('Historical FS'!J82/'Historical FS'!J51,0) -> 10.423854 | ... L40: =IFERROR('Historical FS'!L82/'Historical FS'!L51,0) -> 7.4418133 | N40: =IFERROR(AVERAGE(C40:L40),0) -> 11.925335 | O40: =IFERROR(MEDIAN(C40:L40),0) -> 7.8189378

Sheet Forecasting
B2: ='Data Sheet'!B1&" - "&'Data Sheet'!A17& " Forecasting" -> HINDUSTAN UNILEVER LTD - Sales Forecasting | G2: ='Data Sheet'!B1&" - "&'Data Sheet'!A33& " Forecasting" -> HINDUSTAN UNILEVER LTD - EBITDA Forecasting | L2: ='Data Sheet'!B1&" - "&'Historical FS'!B40& " Forecasting" -> HINDUSTAN UNILEVER LTD - EPS Forecasting
B3: Year Weight | C3: Year | D3: Sales | E3: Sales Growth | G3: Year Weight | H3: Year | I3: EBIDTA | J3: EBIDTA Growth | L3: Year Weight | M3: Year | N3: EPS | O3: EPS Growth
B4: 1 | C4: ='Data Sheet'!B16 -> 42825 | D4: {=TRANSPOSE('Data Sheet'!B17:K17)} -> 33162 | G4: 1 | H4: ='Data Sheet'!B16 -> 42825 | I4: {=TRANSPOSE('Historical FS'!C17:L17)} -> 6623 | L4: 1 | M4: ='Data Sheet'!B16 -> 42825 | N4: {=TRANSPOSE('Historical FS'!C40:L40)} -> 19.308783
B5: =B4+1 -> 2 | C5: =C4+365 -> 43190 | D5: 35545 | E5: =D5/D4-1 -> 0.071859357 | G5: =G4+1 -> 2 | H5: =H4+365 -> 43190 | I5: 7794 | J5: =I5/I4-1 -> 0.17680809 | L5: =L4+1 -> 2 | M5: =M4+365 -> 43190 | N5: 23.880804 | O5: =N5/N4-1 -> 0.23678449
B6: =B5+1 -> 3 | C6: =C5+365 -> 43555 | D6: 39310 | E6: =D6/D5-1 -> 0.10592207 | G6: =G5+1 -> 3 | H6: =H5+365 -> 43555 | I6: 9188 | J6: =I6/I5-1 -> 0.17885553 | L6: =L5+1 -> 3 | M6: =M5+365 -> 43555 | N6: 27.929967 | O6: =N6/N5-1 -> 0.16955725
B7: =B6+1 -> 4 | C7: =C6+365 -> 43920 | D7: 39783 | E7: =D7/D6-1 -> 0.012032562 | G7: =G6+1 -> 4 | H7: =H6+365 -> 43920 | I7: 10160 | J7: =I7/I6-1 -> 0.10579016 | L7: =L6+1 -> 4 | M7: =M6+365 -> 43920 | N7: 30.631005 | O7: =N7/N6-1 -> 0.096707524
B8: =B7+1 -> 5 | C8: =C7+365 -> 44285 | D8: 47028 | E8: =D8/D7-1 -> 0.18211296 | G8: =G7+1 -> 5 | H8: =H7+365 -> 44285 | I8: 11965 | J8: =I8/I7-1 -> 0.17765748 | L8: =L7+1 -> 5 | M8: =M7+365 -> 44285 | N8: 34.763364 | O8: =N8/N7-1 -> 0.13490771
B9: =B8+1 -> 6 | C9: =C8+365 -> 44650 | D9: 52446 | E9: =D9/D8-1 -> 0.11520796 | G9: =G8+1 -> 6 | H9: =H8+365 -> 44650 | I9: 13175 | J9: =I9/I8-1 -> 0.10112829 | L9: =L8+1 -> 6 | M9: =M8+365 -> 44650 | N9: 38.266088 | O9: =N9/N8-1 -> 0.10075906
B10: =B9+1 -> 7 | C10: =C9+365 -> 45015 | D10: 60580 | E10: =D10/D9-1 -> 0.15509286 | G10: =G9+1 -> 7 | H10: =H9+365 -> 45015 | I10: 14531 | J10: =I10/I9-1 -> 0.1029222 | L10: =L9+1 -> 7 | M10: =M9+365 -> 45015 | N10: 42.896663 | O10: =N10/N9-1 -> 0.1210099
B11: =B10+1 -> 8 | C11: =C10+365 -> 45380 | D11: 61896 | E11: =D11/D10-1 -> 0.021723341 | G11: =G10+1 -> 8 | H11: =H10+365 -> 45380 | I11: 15105 | J11: =I11/I10-1 -> 0.039501755 | L11: =L10+1 -> 8 | M11: =M10+365 -> 45380 | N11: 42.181648 | O11: =N11/N10-1 -> -0.01666832
B12: =B11+1 -> 9 | C12: =C11+365 -> 45745 | D12: 61328 | E12: =D12/D11-1 -> -0.0091766835 | G12: =G11+1 -> 9 | H12: =H11+365 -> 45745 | I12: 15101 | J12: =I12/I11-1 -> -0.00026481298 | L12: =L11+1 -> 9 | M12: =M11+365 -> 45745 | N12: 41.364488 | O12: =N12/N11-1 -> -0.019372414
B13: =B12+1 -> 10 | C13: =C12+365 -> 46110 | D13: 64468 | E13: =D13/D12-1 -> 0.051200104 | G13: =G12+1 -> 10 | H13: =H12+365 -> 46110 | I13: 15465 | J13: =I13/I12-1 -> 0.024104364 | L13: =L12+1 -> 10 | M13: =M12+365 -> 46110 | N13: 44.952332 | O13: =N13/N12-1 -> 0.086737319
B14: =B13+1 -> 11 | C14: =C13+365 -> 46475 | D14: =FORECAST(B14,$D$4:$D$13,$B$4:$B$13) -> 70987.067 | E14: =D14/D13-1 -> 0.10112097 | G14: =G13+1 -> 11 | H14: =H13+365 -> 46475 | I14: =FORECAST(G14,$I$4:$I$13,$G$4:$G$13) -> 17731.867 | J14: =I14/I13-1 -> 0.14658045 | L14: =L13+1 -> 11 | M14: =M13+365 -> 46475 | N14: =FORECAST(L14,$N$4:$N$13,$L$4:$L$13) -> 50.108709 | O14: =N14/N13-1 -> 0.11470765
B15: =B14+1 -> 12 | C15: =C14+365 -> 46840 | D15: =FORECAST(B15,$D$4:$D$13,$B$4:$B$13) -> 74883.879 | E15: =D15/D14-1 -> 0.054894677 | G15: =G14+1 -> 12 | H15: =H14+365 -> 46840 | I15: =FORECAST(G15,$I$4:$I$13,$G$4:$G$13) -> 18790.261 | J15: =I15/I14-1 -> 0.059688805 | L15: =L14+1 -> 12 | M15: =M14+365 -> 46840 | N15: =FORECAST(L15,$N$4:$N$13,$L$4:$L$13) -> 52.925289 | O15: =N15/N14-1 -> 0.056209407
B16: =B15+1 -> 13 | C16: =C15+365 -> 47205 | D16: =FORECAST(B16,$D$4:$D$13,$B$4:$B$13) -> 78780.691 | E16: =D16/D15-1 -> 0.052038065 | G16: =G15+1 -> 13 | H16: =H15+365 -> 47205 | I16: =FORECAST(G16,$I$4:$I$13,$G$4:$G$13) -> 19848.655 | J16: =I16/I15-1 -> 0.05632673 | L16: =L15+1 -> 13 | M16: =M15+365 -> 47205 | N16: =FORECAST(L16,$N$4:$N$13,$L$4:$L$13) -> 55.74187 | O16: =N16/N15-1 -> 0.053218052
B17: =B16+1 -> 14 | C17: =C16+365 -> 47570 | D17: =FORECAST(B17,$D$4:$D$13,$B$4:$B$13) -> 82677.503 | E17: =D17/D16-1 -> 0.049464051 | G17: =G16+1 -> 14 | H17: =H16+365 -> 47570 | I17: =FORECAST(G17,$I$4:$I$13,$G$4:$G$13) -> 20907.048 | J17: =I17/I16-1 -> 0.053323208 | L17: =L16+1 -> 14 | M17: =M16+365 -> 47570 | N17: =FORECAST(L17,$N$4:$N$13,$L$4:$L$13) -> 58.558451 | O17: =N17/N16-1 -> 0.050528997
B18: =B17+1 -> 15 | C18: =C17+365 -> 47935 | D18: =FORECAST(B18,$D$4:$D$13,$B$4:$B$13) -> 86574.315 | E18: =D18/D17-1 -> 0.047132678 | G18: =G17+1 -> 15 | H18: =H17+365 -> 47935 | I18: =FORECAST(G18,$I$4:$I$13,$G$4:$G$13) -> 21965.442 | J18: =I18/I17-1 -> 0.050623786 | L18: =L17+1 -> 15 | M18: =M17+365 -> 47935 | N18: =FORECAST(L18,$N$4:$N$13,$L$4:$L$13) -> 61.375032 | O18: =N18/N17-1 -> 0.048098622

Sheet Data Sheet
A1: COMPANY NAME | B1: HINDUSTAN UNILEVER LTD | E1: =IF(B2<>B3, "A NEW VERSION OF THE WORKSHEET IS AVAILABLE", "")
A2: LATEST VERSION | B2: 2.1 | E2: PLEASE DO NOT MAKE ANY CHANGES TO THIS SHEET
A3: CURRENT VERSION | B3: 2.1
A5: META
A6: Number of shares | B6: =IF(B9>0, B9/B8, 0) -> 234.95913
A7: Face Value | B7: 1
A8: Current Price | B8: 2098.4
A9: Market Capitalization | B9: 493038.23
A15: PROFIT & LOSS
A16: Report Date | B16: 42825 | C16: 43190 | D16: 43555 | E16: 43921 | F16: 44286 | G16: 44651 | H16: 45016 | I16: 45382 | J16: 45747 | K16: 46112
A17: Sales | B17: 33162 | C17: 35545 | D17: 39310 | E17: 39783 | F17: 47028 | G17: 52446 | H17: 60580 | I17: 61896 | J17: 61328 | K17: 64468
A18: Raw Material Cost | B18: 13606 | C18: 14233 | D18: 15845 | E18: 15697 | F18: 20141 | G18: 22871 | H18: 28427 | I18: 26822 | J18: 26602 | K18: 29158
A19: Change in Inventory | B19: -144 | C19: 72 | D19: -12 | E19: 108 | F19: 405 | G19: 22 | H19: 75 | I19: 11 | J19: 125 | K19: 429
A20: Power and Fuel | B20: 295 | C20: 295 | D20: 308 | E20: 299 | F20: 339 | G20: 318 | H20: 384 | I20: 446 | J20: 403 | K20: 426
A21: Other Mfr. Exp | B21: 2887 | C21: 2998 | D21: 3041 | E21: 2906 | F21: 2868 | G21: 3354 | H21: 3791 | I21: 3385 | J21: 3687 | K21: 3304
A22: Employee Cost | B22: 1743 | C22: 1860 | D22: 1875 | E22: 1820 | F22: 2358 | G22: 2545 | H22: 2854 | I22: 3009 | J22: 2952 | K22: 3175
A23: Selling and admin | B23: 6689 | C23: 7252 | D23: 7796 | E23: 7620 | F23: 7906 | G23: 8164 | H23: 8785 | I23: 10780 | J23: 10145 | K23: 10744
A24: Other Expenses | B24: 1470 | C24: 1480 | D24: 1553 | E24: 1688 | F24: 2195 | G24: 2359 | H24: 2267 | I24: 2806 | J24: 2966 | K24: 3051
A25: Other Income | B25: 606 | C25: 353 | D25: 322 | E25: 424 | F25: 170 | G25: 219 | H25: 448 | I25: 817 | J25: 1355 | K25: 4923
A26: Depreciation | B26: 432 | C26: 520 | D26: 565 | E26: 1002 | F26: 1074 | G26: 1091 | H26: 1137 | I26: 1216 | J26: 1253 | K26: 1333
A27: Interest | B27: 35 | C27: 26 | D27: 33 | E27: 118 | F27: 117 | G27: 106 | H27: 114 | I27: 334 | J27: 381 | K27: 410
... A31: Dividend Amount | B31: 3672 | C31: 4320 | D31: 4752 | E31: 5400 | F31: 9517.5 | G31: 7990 | H31: 9165 | I31: 9870 | J31: 12455 | K31: 9635
A33: EBITDA | B33: =B30+B29+B27+B26 -> 6920 | C33: =C30+C29+C27+C26 -> 7839 | D33: =D30+D29+D27+D26 -> 9196 | E33: =E30+E29+E27+E26 -> 10277 | F33: =F30+F29+F27+F26 -> 11792 | G33: =G30+G29+G27+G26 -> 13063 | H33: =H30+H29+H27+H26 -> 14572 | I33: =I30+I29+I27+I26 -> 15471 | ... K33: =K30+K29+K27+K26 -> 19943
A40: Quarters
A41: Report Date | B41: 45291 | C41: 45382 | D41: 45473 | E41: 45565 | F41: 45657 | G41: 45747 | H41: 45838 | I41: 45930 | J41: 46022 | K41: 46112
A42: Sales | B42: 15567 | C42: 15210 | D42: 15707 | E42: 15926 | F42: 15556 | G42: 15190 | H42: 16514 | I42: 15919 | J42: 16441 | K42: 16351
A43: Expenses | B43: 11902 | C43: 11675 | D43: 11965 | E43: 12139 | F43: 11867 | G43: 11572 | H43: 12797 | I43: 12137 | J43: 12660 | K43: 12514
A44: Other Income | B44: 184 | C44: 309 | D44: 209 | E44: 203 | F44: 733 | G44: 149 | H44: 74 | I44: 269 | J44: 4048 | K44: 503
A45: Depreciation | B45: 313 | C45: 320 | D45: 329 | E45: 338 | F45: 318 | G45: 318 | H45: 361 | I45: 322 | J45: 337 | K45: 348
A46: Interest | B46: 91 | C46: 105 | D46: 93 | E46: 110 | F46: 109 | G46: 77 | H46: 127 | I46: 124 | J46: 88 | K46: 76
A47: Profit before tax | B47: 3445 | C47: 3419 | D47: 3529 | E47: 3542 | F47: 3995 | G47: 3372 | H47: 3303 | I47: 3605 | J47: 7404 | K47: 3916
A48: Tax | B48: 937 | C48: 858 | D48: 917 | E48: 947 | F48: 1006 | G48: 897 | H48: 535 | I48: 911 | J48: 801 | K48: 922
A49: Net profit | B49: 2509 | C49: 2558 | D49: 2610 | E49: 2591 | F49: 2984 | G49: 2464 | H49: 2756 | I49: 2685 | J49: 6607 | K49: 2992
A50: Operating Profit | B50: 3665 | C50: 3535 | D50: 3742 | E50: 3787 | F50: 3689 | G50: 3618 | H50: 3717 | I50: 3782 | J50: 3781 | K50: 3837
A55: BALANCE SHEET
A56: Report Date | B56: 42825 | C56: 43190 | D56: 43555 | E56: 43921 | F56: 44286 | G56: 44651 | H56: 45016 | I56: 45382 | J56: 45747 | K56: 46112
A57: Equity Share Capital | B57: 216 | C57: 216 | D57: 216 | E57: 216 | F57: 235 | G57: 235 | H57: 235 | I57: 235 | J57: 235 | K57: 235
A58: Reserves | B58: 6528 | C58: 7065 | D58: 7651 | E58: 8013 | F58: 47439 | G58: 48826 | H58: 50069 | I58: 50983 | J58: 49167 | K58: 48504
A59: Borrowings | B59: 277 | D59: 99 | G59: 1043 | H59: 1219 | I59: 1484 | J59: 1648 | K59: 1478
A60: Other Liabilities | B60: 8685 | C60: 10581 | D60: 10663 | E60: 11924 | F60: 21066 | G60: 20402 | H60: 21554 | I60: 25787 | J60: 28813 | K60: 29521
...

Sheet Cash Flow Data
C2: 42064 | D2: 42430 | E2: 42795 | F2: 43160 | G2: 43525 | H2: 43891 | I2: 44256 | J2: 44621 | K2: 44986 | L2: 45352 | M2: 45717 | N2: 46082
B3: Cash from Operating Activity - | C3: 3292 | D3: 4171 | E3: 5185 | F3: 6059 | G3: 5800 | H3: 7623 | I3: 9163 | J3: 9048 | K3: 9991 | L3: 15469 | M3: 11886 | N3: 10999
B4: Profit from operations | C4: 5510 | D4: 6025 | E4: 6512 | F4: 7485 | G4: 8909 | H4: 9723 | I4: 11672 | J4: 12829 | K4: 14089 | L4: 14537 | M4: 14942 | N4: 15153
B5: Receivables | C5: 3 | D5: -257 | E5: 173 | F5: 0 | G5: 0 | H5: 0 | I5: 0 | J5: 0 | K5: 0 | L5: 0 | M5: 0 | N5: 0
B6: Inventory | C6: 91 | D6: 89 | E6: 37 | F6: -146 | G6: -195 | H6: -331 | I6: -543 | J6: -758 | K6: -339 | L6: 74 | M6: -584 | N6: -692
B7: Payables | C7: -327 | D7: 164 | E7: 501 | F7: 0 | G7: 0 | H7: 0 | I7: 0 | J7: 0 | K7: 0 | L7: 0 | M7: 0 | N7: 0
B8: Loans Advances | C8: -148 | D8: 0 | E8: 0 | F8: 0 | G8: 0 | H8: 0 | I8: 0 | J8: 0 | K8: 0 | L8: 0 | M8: 0 | N8: 0
B9: Operating Deposits | C9: 0 | D9: 0 | E9: -46 | F9: 0 | G9: 0 | H9: 0 | I9: 0 | J9: 0 | K9: 0 | L9: 0 | M9: 0 | N9: 0
B10: Other WC items | C10: 38 | D10: -77 | E10: -99 | F10: 982 | G10: -147 | H10: 742 | I10: 442 | J10: -242 | K10: -621 | L10: 1239 | M10: -204 | N10: 1378
B11: Working capital changes | C11: -342 | D11: -81 | E11: 566 | F11: 836 | G11: -342 | H11: 411 | I11: -101 | J11: -1000 | K11: -960 | L11: 1313 | M11: -788 | N11: 686
B12: Direct taxes | C12: -1862 | D12: -1765 | E12: -1859 | F12: -2264 | G12: -2767 | H12: -2505 | I12: -2407 | J12: -2784 | K12: -3138 | L12: -381 | M12: -2268 | N12: -4840
B13: Other operating items | C13: -14 | D13: -8 | E13: -21 | F13: 0 | G13: 0 | H13: 0 | I13: 0 | J13: 0 | K13: 0 | L13: 0 | M13: 0 | N13: 0
B14: Exceptional CF items | C14: 0 | D14: 0 | E14: -13 | F14: 2 | G14: 0 | H14: -6 | I14: -1 | J14: 3 | K14: 0 | L14: 0 | M14: 0 | N14: 0
... B33: Net Cash Flow | C33: -33 | D33: 25 | E33: -202 | F33: 21 | G33: -28 | H33: 2595 | I33: -1374 | J33: -695 | K33: -446 | L33: 111 | M33: 5258 | N33: -3487

Sheet DCF>

Sheet WACC
B2: All figures are in INR unless stated otherwise
B4: Peer Companies
H5: Debt / | I5: Debt / | J5: Levered | K5: Unlevered
B6: Name of the Comapany | D6: Country | E6: Total Debt | F6: Total Equity | G6: Tax Rate 1 | H6: Equity | I6: Capital | J6: Beta 2 | K6: Beta 3
B7: Hind. Unilever | D7: India | E7: ='Beta - Comps'!E3 -> 1478 | F7: ='Beta - Comps'!F3 -> 503669.37 | G7: 0.3 | H7: =E7/F7 -> 0.0029344647 | I7: =E7/(E7+F7) -> 0.0029258788 | J7: =Beta!M7 -> 0.53982593 | K7: =J7/(1+(1-G7)*H7) -> 0.53871934
B8: Marico | D8: India | E8: ='Beta - Comps'!E4 -> 557 | F8: ='Beta - Comps'!F4 -> 110233.91 | G8: 0.3 | H8: =E8/F8 -> 0.0050528916 | I8: =E8/(E8+F8) -> 0.0050274883 | J8: ='Beta - Cal'!C6 -> 0.23570285 | K8: =J8/(1+(1-G8)*H8) -> 0.2348721
B9: Nestle India | D9: India | E9: ='Beta - Comps'!E5 -> 444.16 | F9: ='Beta - Comps'!F5 -> 275180.02 | G9: 0.3 | H9: =E9/F9 -> 0.0016140707 | I9: =E9/(E9+F9) -> 0.0016114696 | J9: ='Beta - Cal'!C7 -> 0.32070112 | K9: =J9/(1+(1-G9)*H9) -> 0.32033919
B10: Godrej Consumer | D10: India | E10: ='Beta - Comps'!E6 -> 4420.52 | F10: ='Beta - Comps'!F6 -> 109646.59 | G10: 0.3 | H10: =E10/F10 -> 0.040316074 | I10: =E10/(E10+F10) -> 0.038753678 | J10: ='Beta - Cal'!C5 -> 0.25252855 | K10: =J10/(1+(1-G10)*H10) -> 0.24559748
B11: Dabur India | D11: India | E11: ='Beta - Comps'!E7 -> 1287.32 | F11: ='Beta - Comps'!F7 -> 75783.25 | G11: 0.3 | H11: =E11/F11 -> 0.016986867 | I11: =E11/(E11+F11) -> 0.016703133 | J11: ='Beta - Cal'!C4 -> 0.27409578 | K11: =J11/(1+(1-G11)*H11) -> 0.27087486
F13: Average | G13: =AVERAGE(G7:G11) -> 0.3 | H13: =AVERAGE(H7:H11) -> 0.013380874 | I13: =AVERAGE(I7:I11) -> 0.01300433 | J13: =AVERAGE(J7:J11) -> 0.32457085 | K13: =AVERAGE(K7:K11) -> 0.32208059
F14: Median | G14: =MEDIAN(G7:G11) -> 0.3 | H14: =MEDIAN(H7:H11) -> 0.0050528916 | I14: =MEDIAN(I7:I11) -> 0.0050274883 | J14: =MEDIAN(J7:J11) -> 0.27409578 | K14: =MEDIAN(K7:K11) -> 0.27087486
B17: Cost of debt | G17: Cost of Equity
B19: Pre - Tax Cost of debt | E19: =410/E7 -> 0.27740189 | G19: Risk Free Rate | K19: 0.0678
B20: Tax Rate | E20: 0.3 | G20: Equity Risk Premium | K20: =Rm!G7-WACC!K19 -> 0.096692308
B21: Post - Tax Cost of debt | E21: =E19*(1-E20) -> 0.19418133 | G21: Levered Beta 4 | K21: =K30 -> 0.27183295
G22: Cost Of Equity | K22: =K19+(K20*K21) -> 0.094084156
B25: Capital Structure | G25: Levered Beta
D27: Current | E27: Target | G27: Companies Median Unlevered Beta | K27: =K14 -> 0.27087486
B28: Total Debt | C28: =E7 -> 1478 | D28: =C28/$C$30 -> 0.0029258788 | E28: =I14 -> 0.0050274883 | G28: Target Debt / Equity | K28: =E32 -> 0.0050528916
B29: Market Capitalisation | C29: =F7 -> 503669.37 | D29: =C29/$C$30 -> 0.99707412 | E29: =E30-E28 -> 0.99497251 | G29: Tax Rate | K29: 0.3
B30: Total Capital | C30: =SUM(C28:C29) -> 505147.37 | D30: =C30/$C$30 -> 1 | E30: 1 | G30: Levered Beta | K30: =K27*(1+(1-K29)*K28) -> 0.27183295
B32: Debt / Equity | D32: =C28/C29 -> 0.0029344647 | E32: =E28/E29 -> 0.0050528916 | G32: Weighted Average Cost Of Capital
B34: Notes: | J34: Total Cost | K34: Total Weight
B35: 1. Tax Rate considered as Marginal Tax Rate for the country | G35: Debt | J35: =E21 -> 0.19418133 | K35: =E28 -> 0.0050274883
B36: 2. Levered Beta is based on 2 years weekly data | G36: Equity | J36: =K22 -> 0.094084156 | K36: =E29 -> 0.99497251
B37: 3. Unlevered Beta = Levered Beta/(1+(1-Tax Rate) x Debt/Equity) | G37: Weighted Average Cost Of Capital | K37: =SUMPRODUCT(J35:J36,K35:K36) -> 0.094587393
B38: 4. Levered Beta = Unlevered Beta*(1+(1-Tax Rate) x Debt/Equity)

Sheet Beta
B2: Regression Beta
B4: ='Data Sheet'!B1&" "& "Weekly Returns" -> HINDUSTAN UNILEVER LTD Weekly Returns | F4: NIFTY Weekly Returns | I4: Beta Drifting | L4: Beta 1 | M4: =SLOPE(D7:D110,G7:G110) -> 0.53982593
L5: Beta 2 | M5: =_xlfn.COVARIANCE.S(D7:D110,G7:G110)/_xlfn.VAR.S(G7:G110) -> 0.53982593
B6: Date | C6: Closing Price | D6: Monthly Return | F6: Closing Price | G6: Monthly Return | I6: Levered Raw Beta | J6: =M7 -> 0.53982593
B7: 45494 | C7: 2700.3 | D7: - | F7: 24834.85 | G7: - | I7: Raw Beta Weight | J7: 0.75 | L7: Beta 3 | M7: =M26 -> 0.53982593
B8: 45501 | C8: 2681.87 | D8: =C8/C7-1 -> -0.0068251676 | F8: 24717.7 | G8: =F8/F7-1 -> -0.0047171616
B9: 45508 | C9: 2736.3 | D9: =C9/C8-1 -> 0.02029554 | F9: 24367.5 | G9: =F9/F8-1 -> -0.014167985 | I9: Market Beta | J9: 1 | L9: SUMMARY OUTPUT
B10: 45515 | C10: 2737.35 | D10: =C10/C9-1 -> 0.00038372985 | F10: 24541.15 | G10: =F10/F9-1 -> 0.0071262953 | I10: Market Beta Weight | J10: 0.25
B11: 45522 | C11: 2804.43 | D11: =C11/C10-1 -> 0.024505452 | F11: 24823.15 | G11: =F11/F10-1 -> 0.011490904 | L11: Regression Statistics
B12: 45529 | C12: 2766.98 | D12: =C12/C11-1 -> -0.013353872 | F12: 25235.9 | G12: =F12/F11-1 -> 0.016627624 | I12: Adjusted Beta | J12: =(J6*J7)+(J9*J10) -> 0.65486945 | L12: Multiple R | M12: 0.37501271
B13: 45536 | C13: 2827.69 | D13: =C13/C12-1 -> 0.021940889 | F13: 24852.15 | G13: =F13/F12-1 -> -0.015206511 | L13: R Square | M13: 0.14063454
B14: 45543 | C14: 2921.32 | D14: =C14/C13-1 -> 0.033111833 | F14: 25356.5 | G14: =F14/F13-1 -> 0.020294019 | L14: Adjusted R Square | M14: 0.13212597
B15: 45550 | C15: 2965.79 | D15: =C15/C14-1 -> 0.015222571 | F15: 25790.95 | G15: =F15/F14-1 -> 0.017133674 | L15: Standard Error | M15: 0.024373937
B16: 45557 | C16: 2954.49 | D16: =C16/C15-1 -> -0.0038101147 | F16: 26178.95 | G16: =F16/F15-1 -> 0.015044037 | L16: Observations | M16: 103
B17: 45564 | C17: 2837.45 | D17: =C17/C16-1 -> -0.039614282 | F17: 25014.6 | G17: =F17/F16-1 -> -0.044476574
B18: 45571 | C18: 2772.16 | D18: =C18/C17-1 -> -0.023010097 | F18: 24964.25 | G18: =F18/F17-1 -> -0.0020128245 | L18: ANOVA
B19: 45578 | C19: 2706.32 | D19: =C19/C18-1 -> -0.023750433 | F19: 24854.05 | G19: =F19/F18-1 -> -0.0044143125 | M19: df | N19: SS | O19: MS | P19: F | Q19: Significance F
B20: 45585 | C20: 2518.02 | D20: =C20/C19-1 -> -0.069577877 | F20: 24180.8 | G20: =F20/F19-1 -> -0.027088141 | L20: Regression | M20: 1 | N20: 0.009819442 | O20: 0.009819442 | P20: 16.528577 | Q20: 9.5027015e-05
B21: 45592 | C21: 2527.44 | D21: =C21/C20-1 -> 0.0037410346 | F21: 24304.35 | G21: =F21/F20-1 -> 0.0051094257 | L21: Residual | M21: 101 | N21: 0.060002967 | O21: 0.00059408878
B22: 45599 | C22: 2507.7 | D22: =C22/C21-1 -> -0.0078102744 | F22: 24148.2 | G22: =F22/F21-1 -> -0.0064247758 | L22: Total | M22: 102 | N22: 0.069822409
B23: 45606 | C23: 2389.2 | D23: =C23/C22-1 -> -0.047254456 | F23: 23532.7 | G23: =F23/F22-1 -> -0.025488442
B24: 45613 | C24: 2445.25 | D24: =C24/C23-1 -> 0.023459735 | F24: 23907.25 | G24: =F24/F23-1 -> 0.015916151 | M24: Coefficients | N24: Standard Error | O24: t Stat | P24: P-value | Q24: Lower 95% | R24: Upper 95% | S24: Lower 95.0% | T24: Upper 95.0%
B25: 45620 | C25: 2496.15 | D25: =C25/C24-1 -> 0.020815867 | F25: 24131.1 | G25: =F25/F24-1 -> 0.0093632685 | L25: Intercept | M25: -0.0018250933 | N25: 0.0024017061 | O25: -0.75991534 | P25: 0.44907537 | Q25: -0.006589432 | R25: 0.0029392455 | S25: -0.006589432 | T25: 0.0029392455
B26: 45627 | C26: 2483.8 | D26: =C26/C25-1 -> -0.0049476193 | F26: 24677.8 | G26: =F26/F25-1 -> 0.022655411 | L26: X Variable 1 | M26: 0.53982593 | N26: 0.13278102 | O26: 4.0655352 | P26: 9.5027015e-05 | Q26: 0.2764241 | R26: 0.80322777 | S26: 0.2764241 | T26: 0.80322777
B27: 45634 | C27: 2390.1 | D27: =C27/C26-1 -> -0.037724454 | F27: 24768.3 | G27: =F27/F26-1 -> 0.0036672637
B28: 45641 | C28: 2333.9 | D28: =C28/C27-1 -> -0.023513661 | F28: 23587.5 | G28: =F28/F27-1 -> -0.047673841
B29: 45648 | C29: 2341.25 | D29: =C29/C28-1 -> 0.0031492352 | F29: 23813.4 | G29: =F29/F28-1 -> 0.0095771065
B30: 45655 | C30: 2406.25 | D30: =C30/C29-1 -> 0.027762947 | F30: 24004.75 | G30: =F30/F29-1 -> 0.0080353918
B31: 45662 | C31: 2442.05 | D31: =C31/C30-1 -> 0.014877922 | F31: 23431.5 | G31: =F31/F30-1 -> -0.02388069
B32: 45669 | C32: 2354 | D32: =C32/C31-1 -> -0.036055773 | F32: 23203.2 | G32: =F32/F31-1 -> -0.0097432943
B33: 45676 | C33: 2368.1 | D33: =C33/C32-1 -> 0.0059898046 | F33: 23092.2 | G33: =F33/F32-1 -> -0.0047838229
B34: 45683 | C34: 2468.8 | D34: =C34/C33-1 -> 0.042523542 | F34: 23508.4 | G34: =F34/F33-1 -> 0.018023402
B35: 45690 | C35: 2363.85 | D35: =C35/C34-1 -> -0.042510531 | F35: 23559.95 | G35: =F35/F34-1 -> 0.0021928332
B36: 45697 | C36: 2318.35 | D36: =C36/C35-1 -> -0.01924826 | F36: 22929.25 | G36: =F36/F35-1 -> -0.026770006
B37: 45704 | C37: 2241.65 | D37: =C37/C36-1 -> -0.033083874 | F37: 22795.9 | G37: =F37/F36-1 -> -0.0058157157
B38: 45711 | C38: 2190.25 | D38: =C38/C37-1 -> -0.022929539 | F38: 22124.7 | G38: =F38/F37-1 -> -0.029443891
... B110: 46215 | C110: 2143.8 | D110: =C110/C109-1 -> -0.0031619083 | F110: 24072.75 | G110: =F110/F109-1 -> -0.0055418083

Sheet Beta - Cal
E3: NIFTY | H3: DABUR | K3: GODREJ | N3: MARICO | Q3: NESTLE
B4: dabur | C4: =SLOPE(F6:F108,I6:I108) -> 0.27409578 | E4: Closing Price | F4: Monthly Return | H4: Closing Price | I4: Monthly Return | K4: Closing Price | L4: Monthly Return | N4: Closing Price | O4: Monthly Return | Q4: Closing Price | R4: Monthly Return
B5: =K3 -> GODREJ | C5: =SLOPE(F6:F108,L6:L108) -> 0.25252855 | E5: 24834.85 | F5: - | H5: 632.45 | K5: 1467.5 | N5: 679.75 | O5: - | Q5: 1238.45
B6: =N3 -> MARICO | C6: =SLOPE(F6:F108,O6:O108) -> 0.23570285 | E6: 24717.7 | F6: =E6/E5-1 -> -0.0047171616 | H6: 627.55 | I6: =H6/H5-1 -> -0.007747648 | K6: 1459.15 | L6: =K6/K5-1 -> -0.0056899489 | N6: 662.4 | O6: =N6/N5-1 -> -0.02552409 | Q6: 1247.55 | R6: =Q6/Q5-1 -> 0.0073478945
B7: =Q3 -> NESTLE | C7: =SLOPE(F6:F108,R6:R108) -> 0.32070112 | E7: 24367.5 | F7: =E7/E6-1 -> -0.014167985 | H7: 623.95 | I7: =H7/H6-1 -> -0.0057365947 | K7: 1444.8 | L7: =K7/K6-1 -> -0.0098344927 | N7: 653 | O7: =N7/N6-1 -> -0.014190821 | Q7: 1252.35 | R7: =Q7/Q6-1 -> 0.0038475412
E8: 24541.15 | F8: =E8/E7-1 -> 0.0071262953 | H8: 617.6 | I8: =H8/H7-1 -> -0.010177098 | K8: 1405.05 | L8: =K8/K7-1 -> -0.027512458 | N8: 661.05 | O8: =N8/N7-1 -> 0.012327718 | Q8: 1262.72 | R8: =Q8/Q7-1 -> 0.0082804328
E9: 24823.15 | F9: =E9/E8-1 -> 0.011490904 | H9: 643.25 | I9: =H9/H8-1 -> 0.041531736 | K9: 1428.35 | L9: =K9/K8-1 -> 0.01658304 | N9: 678.2 | O9: =N9/N8-1 -> 0.025943575 | Q9: 1264.6 | R9: =Q9/Q8-1 -> 0.0014888495
E10: 25235.9 | F10: =E10/E9-1 -> 0.016627624 | H10: 637.15 | I10: =H10/H9-1 -> -0.0094830937 | K10: 1481.2 | L10: =K10/K9-1 -> 0.037000735 | N10: 647.15 | O10: =N10/N9-1 -> -0.045782955 | Q10: 1250.38 | R10: =Q10/Q9-1 -> -0.011244662
E11: 24852.15 | F11: =E11/E10-1 -> -0.015206511 | H11: 644.4 | I11: =H11/H10-1 -> 0.011378796 | K11: 1443.45 | L11: =K11/K10-1 -> -0.025486092 | N11: 665.25 | O11: =N11/N10-1 -> 0.027968786 | Q11: 1251.6 | R11: =Q11/Q10-1 -> 0.00097570339
E12: 25356.5 | F12: =E12/E11-1 -> 0.020294019 | H12: 660.9 | I12: =H12/H11-1 -> 0.025605214 | K12: 1491.3 | L12: =K12/K11-1 -> 0.033149745 | N12: 681.95 | O12: =N12/N11-1 -> 0.025103345 | Q12: 1265.7 | R12: =Q12/Q11-1 -> 0.01126558
E13: 25790.95 | F13: =E13/E12-1 -> 0.017133674 | H13: 667.55 | I13: =H13/H12-1 -> 0.010062037 | K13: 1456.6 | L13: =K13/K12-1 -> -0.023268289 | N13: 709 | O13: =N13/N12-1 -> 0.039665665 | Q13: 1349.78 | R13: =Q13/Q12-1 -> 0.066429644
E14: 26178.95 | F14: =E14/E13-1 -> 0.015044037 | H14: 633 | I14: =H14/H13-1 -> -0.051756423 | K14: 1388.65 | L14: =K14/K13-1 -> -0.046649732 | N14: 692.45 | O14: =N14/N13-1 -> -0.023342736 | Q14: 1372.85 | R14: =Q14/Q13-1 -> 0.017091674
E15: 25014.6 | F15: =E15/E14-1 -> -0.044476574 | H15: 572.45 | I15: =H15/H14-1 -> -0.095655608 | K15: 1343.25 | L15: =K15/K14-1 -> -0.032693623 | N15: 690.2 | O15: =N15/N14-1 -> -0.0032493321 | Q15: 1299.07 | R15: =Q15/Q14-1 -> -0.053742215
E16: 24964.25 | F16: =E16/E15-1 -> -0.0020128245 | H16: 570.85 | I16: =H16/H15-1 -> -0.0027950039 | K16: 1315.7 | L16: =K16/K15-1 -> -0.020509957 | N16: 685.5 | O16: =N16/N15-1 -> -0.0068096204 | Q16: 1255.9 | R16: =Q16/Q15-1 -> -0.033231466
E17: 24854.05 | F17: =E17/E16-1 -> -0.0044143125 | H17: 571.4 | I17: =H17/H16-1 -> 0.00096347552 | K17: 1336.15 | L17: =K17/K16-1 -> 0.015543057 | N17: 669.3 | O17: =N17/N16-1 -> -0.023632385 | Q17: 1175.13 | R17: =Q17/Q16-1 -> -0.064312445
E18: 24180.8 | F18: =E18/E17-1 -> -0.027088141 | H18: 538.7 | I18: =H18/H17-1 -> -0.057227861 | K18: 1291.25 | L18: =K18/K17-1 -> -0.033604012 | N18: 640.1 | O18: =N18/N17-1 -> -0.043627671 | Q18: 1130.35 | R18: =Q18/Q17-1 -> -0.038106422
E19: 24304.35 | F19: =E19/E18-1 -> 0.0051094257 | H19: 542.55 | I19: =H19/H18-1 -> 0.007146835 | K19: 1275.1 | L19: =K19/K18-1 -> -0.01250726 | N19: 645.95 | O19: =N19/N18-1 -> 0.009139197 | Q19: 1141.15 | R19: =Q19/Q18-1 -> 0.0095545627
... E108: 24072.75 | F108: =E108/E107-1 -> -0.0055418083 | H108: 427.2 | I108: =H108/H107-1 -> -0.0367531 | K108: 1071.9 | L108: =K108/K107-1 -> -0.015159868 | N108: 844 | O108: =N108/N107-1 -> -0.0099706745 | Q108: 1427.2 | R108: =Q108/Q107-1 -> -0.019241341

Sheet Beta - Comps
B2: S.No. | C2: Name | D2: CMP Rs. | E2: Debt Rs.Cr. | F2: Mar Cap Rs.Cr. | G2: Debt / Eq
B3: 1 | C3: Hind. Unilever | D3: 2143.8 | E3: 1478 | F3: 503669.37 | G3: 0.03
B4: 2 | C4: Marico | D4: 844 | E4: 557 | F4: 110233.91 | G4: 0.13
B5: 3 | C5: Nestle India | D5: 1427.2 | E5: 444.16 | F5: 275180.02 | G5: 0.08
B6: 4 | C6: Godrej Consumer | D6: 1071.9 | E6: 4420.52 | F6: 109646.59 | G6: 0.35
B7: 5 | C7: Dabur India | D7: 427.2 | E7: 1287.32 | F7: 75783.25 | G7: 0.11

Sheet Rm
B2: Return on Markets
B4: Year | C4: Annual
B5: 2000 | C5: -0.1465 | E5: Average Return | G5: =AVERAGE(C5:C30) -> 0.15149231
B6: 2001 | C6: -0.1618 | E6: Dividend Yield | G6: 0.013
B7: 2002 | C7: 0.0325 | E7: Total Market Returns | G7: =SUM(G5:G6) -> 0.16449231
B8: 2003 | C8: 0.719
B9: 2004 | C9: 0.1068
B10: 2005 | C10: 0.3634
B11: 2006 | C11: 0.3983
B12: 2007 | C12: 0.5477
B13: 2008 | C13: -0.5179
B14: 2009 | C14: 0.7576
